Workbook

Sheet Sheet1
A1: Row # | B1: Class | C1: AGE | D1: LIVER_FIRM | E1: BILIRUBIN | F1: ALBUMIN | H1: Row # | I1: Class | J1: age_norm | K1: LIVER_FIRM_NORM | L1: BILIRUBIN_NORM | M1: ALBUMIN_NORM
A2: 1 | B2: 2 | C2: 38 | D2: 1 | E2: 0.7 | F2: 4.2 | H2: 1 | I2: 2 | J2: =(C2-0)/(100-0) -> 0.38 | K2: =(D2-1)/(2-1) -> 0 | L2: =(E2-0)/(5-0) -> 0.14 | M2: =(F2-0)/(5-0) -> 0.84
A3: 2 | B3: 1 | C3: 47 | D3: 1 | E3: 1 | F3: 2.6 | H3: 2 | I3: 1 | J3: =(C3-0)/(100-0) -> 0.47 | K3: =(D3-1)/(2-1) -> 0 | L3: =(E3-0)/(5-0) -> 0.2 | M3: =(F3-0)/(5-0) -> 0.52
A4: 3 | B4: 1 | C4: 47 | D4: 1 | E4: 1.7 | F4: 2.1 | H4: 3 | I4: 1 | J4: =(C4-0)/(100-0) -> 0.47 | K4: =(D4-1)/(2-1) -> 0 | L4: =(E4-0)/(5-0) -> 0.34 | M4: =(F4-0)/(5-0) -> 0.42
A5: 4 | B5: 2 | C5: 38 | D5: 2 | E5: 0.7 | F5: 4.1 | H5: 4 | I5: 2 | J5: =(C5-0)/(100-0) -> 0.38 | K5: =(D5-1)/(2-1) -> 1 | L5: =(E5-0)/(5-0) -> 0.14 | M5: =(F5-0)/(5-0) -> 0.82
A6: 5 | B6: 1 | C6: 48 | D6: 1 | E6: 4.8 | F6: 2.7 | H6: 5 | I6: 1 | J6: =(C6-0)/(100-0) -> 0.48 | K6: =(D6-1)/(2-1) -> 0 | L6: =(E6-0)/(5-0) -> 0.96 | M6: =(F6-0)/(5-0) -> 0.54
A7: 6 | B7: 1 | C7: 42 | D7: 2 | E7: 0.5 | F7: 3.8 | H7: 6 | I7: 1 | J7: =(C7-0)/(100-0) -> 0.42 | K7: =(D7-1)/(2-1) -> 1 | L7: =(E7-0)/(5-0) -> 0.1 | M7: =(F7-0)/(5-0) -> 0.76
A8: 7 | B8: 1 | C8: 41 | D8: 1 | E8: 4.2 | F8: 3.4 | H8: 7 | I8: 1 | J8: =(C8-0)/(100-0) -> 0.41 | K8: =(D8-1)/(2-1) -> 0 | L8: =(E8-0)/(5-0) -> 0.84 | M8: =(F8-0)/(5-0) -> 0.68
A9: 8 | B9: 1 | C9: 38 | D9: 1 | E9: 0.4 | F9: 3.8 | H9: 8 | I9: 1 | J9: =(C9-0)/(100-0) -> 0.38 | K9: =(D9-1)/(2-1) -> 0 | L9: =(E9-0)/(5-0) -> 0.08 | M9: =(F9-0)/(5-0) -> 0.76
A10: 9 | B10: 2 | C10: 34 | D10: 2 | E10: 0.9 | F10: 4 | H10: 9 | I10: 2 | J10: =(C10-0)/(100-0) -> 0.34 | K10: =(D10-1)/(2-1) -> 1 | L10: =(E10-0)/(5-0) -> 0.18 | M10: =(F10-0)/(5-0) -> 0.8
A11: 10 | B11: 1 | C11: 33 | D11: 2 | E11: 0.7 | F11: 3 | H11: 10 | I11: 1 | J11: =(C11-0)/(100-0) -> 0.33 | K11: =(D11-1)/(2-1) -> 1 | L11: =(E11-0)/(5-0) -> 0.14 | M11: =(F11-0)/(5-0) -> 0.6
A12: 11 | B12: 1 | C12: 50 | D12: 1 | E12: 2.8 | F12: 2.4 | H12: 11 | I12: 1 | J12: =(C12-0)/(100-0) -> 0.5 | K12: =(D12-1)/(2-1) -> 0 | L12: =(E12-0)/(5-0) -> 0.56 | M12: =(F12-0)/(5-0) -> 0.48
A13: 12 | B13: 2 | C13: 38 | D13: 2 | E13: 2 | F13: 2.9 | H13: 12 | I13: 2 | J13: =(C13-0)/(100-0) -> 0.38 | K13: =(D13-1)/(2-1) -> 1 | L13: =(E13-0)/(5-0) -> 0.4 | M13: =(F13-0)/(5-0) -> 0.58
... A31: 30 | B31: 2 | C31: 22 | D31: 2 | E31: 0.9 | F31: 4.2 | H31: 30 | I31: 2 | J31: =(C31-0)/(100-0) -> 0.22 | K31: =(D31-1)/(2-1) -> 1 | L31: =(E31-0)/(5-0) -> 0.18 | M31: =(F31-0)/(5-0) -> 0.84
A33: Min= | C33: 0 | D33: 1 | E33: 0 | F33: 0
A34: Max= | C34: 100 | D34: 2 | E34: 5 | F34: 5

Sheet Sheet2
A1: Test | B1: Training | C1: Distance | D1: Class
A2: Test 1 | B2: Training 1 | C2: =SQRT((Sheet1!J2-Sheet1!J7)^2+(Sheet1!K2-Sheet1!K7)^2+(Sheet1!L2-Sheet1!L7)^2+(Sheet1!M2-Sheet1!M7)^2) -> 1.0047885 | D2: =Sheet1!I7 -> 1
B3: Training 2 | C3: =SQRT((Sheet1!J3-Sheet1!J8)^2+(Sheet1!K3-Sheet1!K8)^2+(Sheet1!L3-Sheet1!L8)^2+(Sheet1!M3-Sheet1!M8)^2) -> 0.66241981 | D3: =Sheet1!I8 -> 1
B4: Training 3 | C4: =SQRT((Sheet1!J4-Sheet1!J9)^2+(Sheet1!K4-Sheet1!K9)^2+(Sheet1!L4-Sheet1!L9)^2+(Sheet1!M4-Sheet1!M9)^2) -> 0.43737855 | D4: =Sheet1!I9 -> 1
B5: Training 4 | C5: =SQRT((Sheet1!J5-Sheet1!J10)^2+(Sheet1!K5-Sheet1!K10)^2+(Sheet1!L5-Sheet1!L10)^2+(Sheet1!M5-Sheet1!M10)^2) -> 0.06 | D5: =Sheet1!I10 -> 2
B6: Training 5 | C6: =SQRT((Sheet1!J6-Sheet1!J11)^2+(Sheet1!K6-Sheet1!K11)^2+(Sheet1!L6-Sheet1!L11)^2+(Sheet1!M6-Sheet1!M11)^2) -> 1.3032651 | D6: =Sheet1!I11 -> 1
B7: Training 6 | C7: =SQRT((Sheet1!J7-Sheet1!J12)^2+(Sheet1!K7-Sheet1!K12)^2+(Sheet1!L7-Sheet1!L12)^2+(Sheet1!M7-Sheet1!M12)^2) -> 1.1385956 | D7: =Sheet1!I12 -> 1
B8: Training 7 | C8: =SQRT((Sheet1!J8-Sheet1!J13)^2+(Sheet1!K8-Sheet1!K13)^2+(Sheet1!L8-Sheet1!L13)^2+(Sheet1!M8-Sheet1!M13)^2) -> 1.0974972 | D8: =Sheet1!I13 -> 2
B9: Training 8 | C9: =SQRT((Sheet1!J9-Sheet1!J14)^2+(Sheet1!K9-Sheet1!K14)^2+(Sheet1!L9-Sheet1!L14)^2+(Sheet1!M9-Sheet1!M14)^2) -> 1.0092076 | D9: =Sheet1!I14 -> 2
B10: Training 9 | C10: =SQRT((Sheet1!J10-Sheet1!J15)^2+(Sheet1!K10-Sheet1!K15)^2+(Sheet1!L10-Sheet1!L15)^2+(Sheet1!M10-Sheet1!M15)^2) -> 0.44181444 | D10: =Sheet1!I15 -> 2
B11: Training 10 | C11: =SQRT((Sheet1!J11-Sheet1!J16)^2+(Sheet1!K11-Sheet1!K16)^2+(Sheet1!L11-Sheet1!L16)^2+(Sheet1!M11-Sheet1!M16)^2) -> 1.0223991 | D11: =Sheet1!I16 -> 2
B12: Training 11 | C12: =SQRT((Sheet1!J12-Sheet1!J17)^2+(Sheet1!K12-Sheet1!K17)^2+(Sheet1!L12-Sheet1!L17)^2+(Sheet1!M12-Sheet1!M17)^2) -> 0.55172457 | D12: =Sheet1!I17 -> 2
B13: Training 12 | C13: =SQRT((Sheet1!J13-Sheet1!J18)^2+(Sheet1!K13-Sheet1!K18)^2+(Sheet1!L13-Sheet1!L18)^2+(Sheet1!M13-Sheet1!M18)^2) -> 0.17233688 | D13: =Sheet1!I18 -> 1
B14: Training 13 | C14: =SQRT((Sheet1!J14-Sheet1!J19)^2+(Sheet1!K14-Sheet1!K19)^2+(Sheet1!L14-Sheet1!L19)^2+(Sheet1!M14-Sheet1!M19)^2) -> 0.23853721 | D14: =Sheet1!I19 -> 2
... B29: Training 28 | C29: =SQRT((Sheet1!J29-Sheet1!J34)^2+(Sheet1!K29-Sheet1!K34)^2+(Sheet1!L29-Sheet1!L34)^2+(Sheet1!M29-Sheet1!M34)^2) -> 1.4942557 | D29: =Sheet1!I34 -> 0
A30: Test 2 | B30: Training 1 | C30: =SQRT((Sheet1!J3-Sheet1!J7)^2+(Sheet1!K3-Sheet1!K7)^2+(Sheet1!L3-Sheet1!L7)^2+(Sheet1!M3-Sheet1!M7)^2) -> 1.0344564 | D30: =Sheet1!I7 -> 1
B31: Training 2 | C31: =SQRT((Sheet1!J4-Sheet1!J8)^2+(Sheet1!K4-Sheet1!K8)^2+(Sheet1!L4-Sheet1!L8)^2+(Sheet1!M4-Sheet1!M8)^2) -> 0.56674509 | D31: =Sheet1!I8 -> 1
B32: Training 3 | C32: =SQRT((Sheet1!J5-Sheet1!J9)^2+(Sheet1!K5-Sheet1!K9)^2+(Sheet1!L5-Sheet1!L9)^2+(Sheet1!M5-Sheet1!M9)^2) -> 1.0035935 | D32: =Sheet1!I9 -> 1
B33: Training 4 | C33: =SQRT((Sheet1!J6-Sheet1!J10)^2+(Sheet1!K6-Sheet1!K10)^2+(Sheet1!L6-Sheet1!L10)^2+(Sheet1!M6-Sheet1!M10)^2) -> 1.3021521 | D33: =Sheet1!I10 -> 2
B34: Training 5 | C34: =SQRT((Sheet1!J7-Sheet1!J11)^2+(Sheet1!K7-Sheet1!K11)^2+(Sheet1!L7-Sheet1!L11)^2+(Sheet1!M7-Sheet1!M11)^2) -> 0.18788294 | D34: =Sheet1!I11 -> 1
B35: Training 6 | C35: =SQRT((Sheet1!J8-Sheet1!J12)^2+(Sheet1!K8-Sheet1!K12)^2+(Sheet1!L8-Sheet1!L12)^2+(Sheet1!M8-Sheet1!M12)^2) -> 0.35566838 | D35: =Sheet1!I12 -> 1
B36: Training 7 | C36: =SQRT((Sheet1!J9-Sheet1!J13)^2+(Sheet1!K9-Sheet1!K13)^2+(Sheet1!L9-Sheet1!L13)^2+(Sheet1!M9-Sheet1!M13)^2) -> 1.0652699 | D36: =Sheet1!I13 -> 2
B37: Training 8 | C37: =SQRT((Sheet1!J10-Sheet1!J14)^2+(Sheet1!K10-Sheet1!K14)^2+(Sheet1!L10-Sheet1!L14)^2+(Sheet1!M10-Sheet1!M14)^2) -> 0.083066239 | D37: =Sheet1!I14 -> 2
B38: Training 9 | C38: =SQRT((Sheet1!J11-Sheet1!J15)^2+(Sheet1!K11-Sheet1!K15)^2+(Sheet1!L11-Sheet1!L15)^2+(Sheet1!M11-Sheet1!M15)^2) -> 0.49244289 | D38: =Sheet1!I15 -> 2
B39: Training 10 | C39: =SQRT((Sheet1!J12-Sheet1!J16)^2+(Sheet1!K12-Sheet1!K16)^2+(Sheet1!L12-Sheet1!L16)^2+(Sheet1!M12-Sheet1!M16)^2) -> 0.55317267 | D39: =Sheet1!I16 -> 2
B40: Training 11 | C40: =SQRT((Sheet1!J13-Sheet1!J17)^2+(Sheet1!K13-Sheet1!K17)^2+(Sheet1!L13-Sheet1!L17)^2+(Sheet1!M13-Sheet1!M17)^2) -> 1.0807405 | D40: =Sheet1!I17 -> 2
B41: Training 12 | C41: =SQRT((Sheet1!J14-Sheet1!J18)^2+(Sheet1!K14-Sheet1!K18)^2+(Sheet1!L14-Sheet1!L18)^2+(Sheet1!M14-Sheet1!M18)^2) -> 0.22715633 | D41: =Sheet1!I18 -> 1
B42: Training 13 | C42: =SQRT((Sheet1!J15-Sheet1!J19)^2+(Sheet1!K15-Sheet1!K19)^2+(Sheet1!L15-Sheet1!L19)^2+(Sheet1!M15-Sheet1!M19)^2) -> 0.3 | D42: =Sheet1!I19 -> 2
... B57: Training 28 | C57: =SQRT((Sheet1!J30-Sheet1!J34)^2+(Sheet1!K30-Sheet1!K34)^2+(Sheet1!L30-Sheet1!L34)^2+(Sheet1!M30-Sheet1!M34)^2) -> 1.3626812 | D57: =Sheet1!I34 -> 0
A58: Test 3 | B58: Training 1 | C58: =SQRT((Sheet1!J4-Sheet1!J7)^2+(Sheet1!K4-Sheet1!K7)^2+(Sheet1!L4-Sheet1!L7)^2+(Sheet1!M4-Sheet1!M7)^2) -> 1.084297 | D58: =Sheet1!I7 -> 1
B59: Training 2 | C59: =SQRT((Sheet1!J5-Sheet1!J8)^2+(Sheet1!K5-Sheet1!K8)^2+(Sheet1!L5-Sheet1!L8)^2+(Sheet1!M5-Sheet1!M8)^2) -> 1.229024 | D59: =Sheet1!I8 -> 1
B60: Training 3 | C60: =SQRT((Sheet1!J6-Sheet1!J9)^2+(Sheet1!K6-Sheet1!K9)^2+(Sheet1!L6-Sheet1!L9)^2+(Sheet1!M6-Sheet1!M9)^2) -> 0.91257876 | D60: =Sheet1!I9 -> 1
B61: Training 4 | C61: =SQRT((Sheet1!J7-Sheet1!J10)^2+(Sheet1!K7-Sheet1!K10)^2+(Sheet1!L7-Sheet1!L10)^2+(Sheet1!M7-Sheet1!M10)^2) -> 0.12 | D61: =Sheet1!I10 -> 2
B62: Training 5 | C62: =SQRT((Sheet1!J8-Sheet1!J11)^2+(Sheet1!K8-Sheet1!K11)^2+(Sheet1!L8-Sheet1!L11)^2+(Sheet1!M8-Sheet1!M11)^2) -> 1.2258874 | D62: =Sheet1!I11 -> 1
B63: Training 6 | C63: =SQRT((Sheet1!J9-Sheet1!J12)^2+(Sheet1!K9-Sheet1!K12)^2+(Sheet1!L9-Sheet1!L12)^2+(Sheet1!M9-Sheet1!M12)^2) -> 0.56850682 | D63: =Sheet1!I12 -> 1
B64: Training 7 | C64: =SQRT((Sheet1!J10-Sheet1!J13)^2+(Sheet1!K10-Sheet1!K13)^2+(Sheet1!L10-Sheet1!L13)^2+(Sheet1!M10-Sheet1!M13)^2) -> 0.31368774 | D64: =Sheet1!I13 -> 2
B65: Training 8 | C65: =SQRT((Sheet1!J11-Sheet1!J14)^2+(Sheet1!K11-Sheet1!K14)^2+(Sheet1!L11-Sheet1!L14)^2+(Sheet1!M11-Sheet1!M14)^2) -> 0.17204651 | D65: =Sheet1!I14 -> 2
B66: Training 9 | C66: =SQRT((Sheet1!J12-Sheet1!J15)^2+(Sheet1!K12-Sheet1!K15)^2+(Sheet1!L12-Sheet1!L15)^2+(Sheet1!M12-Sheet1!M15)^2) -> 1.1649893 | D66: =Sheet1!I15 -> 2
B67: Training 10 | C67: =SQRT((Sheet1!J13-Sheet1!J16)^2+(Sheet1!K13-Sheet1!K16)^2+(Sheet1!L13-Sheet1!L16)^2+(Sheet1!M13-Sheet1!M16)^2) -> 1.0616968 | D67: =Sheet1!I16 -> 2
B68: Training 11 | C68: =SQRT((Sheet1!J14-Sheet1!J17)^2+(Sheet1!K14-Sheet1!K17)^2+(Sheet1!L14-Sheet1!L17)^2+(Sheet1!M14-Sheet1!M17)^2) -> 1.0619322 | D68: =Sheet1!I17 -> 2
...

Sheet Sheet3
A1: Test Instance | B1: Actual Class | C1: k=1 Nearest | D1: k=1 Class | E1: k=1 Correct? | F1: k=2 N1 Class | G1: k=2 N2 Class | H1: k=2 Prediction | I1: k=2 Correct? | J1: k=3 N1 Class | K1: k=3 N2 Class | L1: k=3 N3 Class | M1: k=3 Prediction | N1: k=3 Correct?
A2: Test 1 | B2: =Sheet1!B2 -> 2 | C2: =INDEX(Sheet2!B2:B29,MATCH(SMALL(Sheet2!C2:C29,1),Sheet2!C2:C29,0)) -> Training 4 | D2: =INDEX(Sheet2!D2:D29,MATCH(SMALL(Sheet2!C2:C29,1),Sheet2!C2:C29,0)) -> 2 | E2: =B2=D2 -> TRUE | F2: =INDEX(Sheet2!D2:D29,MATCH(SMALL(Sheet2!C2:C29,1),Sheet2!C2:C29,0)) -> 2 | G2: =INDEX(Sheet2!D2:D29,MATCH(SMALL(Sheet2!C2:C29,2),Sheet2!C2:C29,0)) -> 2 | H2: =IF(COUNTIF(F2:G2,1)>COUNTIF(F2:G2,2),1,2) -> 2 | I2: =B2=H2 -> TRUE | J2: =INDEX(Sheet2!D2:D29,MATCH(SMALL(Sheet2!C2:C29,1),Sheet2!C2:C29,0)) -> 2 | K2: =INDEX(Sheet2!D2:D29,MATCH(SMALL(Sheet2!C2:C29,2),Sheet2!C2:C29,0)) -> 2 | L2: =INDEX(Sheet2!D2:D29,MATCH(SMALL(Sheet2!C2:C29,3),Sheet2!C2:C29,0)) -> 1 | M2: =IF(COUNTIF(J2:L2,1)>COUNTIF(J2:L2,2),1,2) -> 2 | N2: =B2=M2 -> TRUE
A3: Test 2 | B3: =Sheet1!B3 -> 1 | C3: =INDEX(Sheet2!B30:B57,MATCH(SMALL(Sheet2!C30:C57,1),Sheet2!C30:C57,0)) -> Training 8 | D3: =INDEX(Sheet2!D30:D57,MATCH(SMALL(Sheet2!C30:C57,1),Sheet2!C30:C57,0)) -> 2 | E3: =B3=D3 -> FALSE | F3: =INDEX(Sheet2!D30:D57,MATCH(SMALL(Sheet2!C30:C57,1),Sheet2!C30:C57,0)) -> 2 | G3: =INDEX(Sheet2!D30:D57,MATCH(SMALL(Sheet2!C30:C57,2),Sheet2!C30:C57,0)) -> 2 | H3: =IF(COUNTIF(F3:G3,1)>COUNTIF(F3:G3,2),1,2) -> 2 | I3: =B3=H3 -> FALSE | J3: =INDEX(Sheet2!D30:D57,MATCH(SMALL(Sheet2!C30:C57,1),Sheet2!C30:C57,0)) -> 2 | K3: =INDEX(Sheet2!D30:D57,MATCH(SMALL(Sheet2!C30:C57,2),Sheet2!C30:C57,0)) -> 2 | L3: =INDEX(Sheet2!D30:D57,MATCH(SMALL(Sheet2!C30:C57,3),Sheet2!C30:C57,0)) -> 1 | M3: =IF(COUNTIF(J3:L3,1)>COUNTIF(J3:L3,2),1,2) -> 2 | N3: =B3=M3 -> FALSE
A4: Test 3 | B4: =Sheet1!B4 -> 1 | C4: =INDEX(Sheet2!B58:B82,MATCH(SMALL(Sheet2!C58:C82,1),Sheet2!C58:C82,0)) -> Training 4 | D4: =INDEX(Sheet2!D58:D82,MATCH(SMALL(Sheet2!C58:C82,1),Sheet2!C58:C82,0)) -> 2 | E4: =B4=D4 -> FALSE | F4: =INDEX(Sheet2!D58:D82,MATCH(SMALL(Sheet2!C58:C82,1),Sheet2!C58:C82,0)) -> 2 | G4: =INDEX(Sheet2!D58:D82,MATCH(SMALL(Sheet2!C58:C82,2),Sheet2!C58:C82,0)) -> 2 | H4: =IF(COUNTIF(F4:G4,1)>COUNTIF(F4:G4,2),1,2) -> 2 | I4: =B4=H4 -> FALSE | J4: =INDEX(Sheet2!D58:D82,MATCH(SMALL(Sheet2!C58:C82,1),Sheet2!C58:C82,0)) -> 2 | K4: =INDEX(Sheet2!D58:D82,MATCH(SMALL(Sheet2!C58:C82,2),Sheet2!C58:C82,0)) -> 2 | L4: =INDEX(Sheet2!D58:D82,MATCH(SMALL(Sheet2!C58:C82,3),Sheet2!C58:C82,0)) -> 2 | M4: =IF(COUNTIF(J4:L4,1)>COUNTIF(J4:L4,2),1,2) -> 2 | N4: =B4=M4 -> FALSE
A5: Test 4 | B5: =Sheet1!B5 -> 2 | C5: =INDEX(Sheet2!B83:B110,MATCH(SMALL(Sheet2!C83:C110,1),Sheet2!C83:C110,0)) -> Training 28 | D5: =INDEX(Sheet2!D83:D110,MATCH(SMALL(Sheet2!C83:C110,1),Sheet2!C83:C110,0)) -> 0 | E5: =B5=D5 -> FALSE | F5: =INDEX(Sheet2!D83:D110,MATCH(SMALL(Sheet2!C83:C110,1),Sheet2!C83:C110,0)) -> 0 | G5: =INDEX(Sheet2!D83:D110,MATCH(SMALL(Sheet2!C83:C110,2),Sheet2!C83:C110,0)) -> 1 | H5: =IF(COUNTIF(F5:G5,1)>COUNTIF(F5:G5,2),1,2) -> 1 | I5: =B5=H5 -> FALSE | J5: =INDEX(Sheet2!D83:D110,MATCH(SMALL(Sheet2!C83:C110,1),Sheet2!C83:C110,0)) -> 0 | K5: =INDEX(Sheet2!D83:D110,MATCH(SMALL(Sheet2!C83:C110,2),Sheet2!C83:C110,0)) -> 1 | L5: =INDEX(Sheet2!D83:D110,MATCH(SMALL(Sheet2!C83:C110,3),Sheet2!C83:C110,0)) -> 2 | M5: =IF(COUNTIF(J5:L5,1)>COUNTIF(J5:L5,2),1,2) -> 2 | N5: =B5=M5 -> TRUE
A6: Test 5 | B6: =Sheet1!B6 -> 1 | C6: =INDEX(Sheet2!B111:B138,MATCH(SMALL(Sheet2!C111:C138,1),Sheet2!C111:C138,0)) -> Training 27 | D6: =INDEX(Sheet2!D111:D138,MATCH(SMALL(Sheet2!C111:C138,1),Sheet2!C111:C138,0)) -> 0 | E6: =B6=D6 -> FALSE | F6: =INDEX(Sheet2!D111:D138,MATCH(SMALL(Sheet2!C111:C138,1),Sheet2!C111:C138,0)) -> 0 | G6: =INDEX(Sheet2!D111:D138,MATCH(SMALL(Sheet2!C111:C138,2),Sheet2!C111:C138,0)) -> 0 | H6: =IF(COUNTIF(F6:G6,1)>COUNTIF(F6:G6,2),1,2) -> 2 | I6: =B6=H6 -> FALSE | J6: =INDEX(Sheet2!D111:D138,MATCH(SMALL(Sheet2!C111:C138,1),Sheet2!C111:C138,0)) -> 0 | K6: =INDEX(Sheet2!D111:D138,MATCH(SMALL(Sheet2!C111:C138,2),Sheet2!C111:C138,0)) -> 0 | L6: =INDEX(Sheet2!D111:D138,MATCH(SMALL(Sheet2!C111:C138,3),Sheet2!C111:C138,0)) -> 1 | M6: =IF(COUNTIF(J6:L6,1)>COUNTIF(J6:L6,2),1,2) -> 1 | N6: =B6=M6 -> TRUE

Sheet Sheet4
A1: k Value | B1: TP | C1: FP | D1: TN | E1: FN | F1: Accuracy | G1: Precision | H1: Recall | I1: F1 Score
A2: K=1 | B2: =COUNTIFS(Sheet3!B2:B6,1,Sheet3!D2:D6,1) -> 0 | C2: =COUNTIFS(Sheet3!B2:B6,2,Sheet3!D2:D6,1) -> 0 | D2: =COUNTIFS(Sheet3!B2:B6,2,Sheet3!D2:D6,2) -> 1 | E2: =COUNTIFS(Sheet3!B2:B6,1,Sheet3!D2:D6,2) -> 2 | F2: =(B2+D2)/(B2+C2+D2+E2) -> 0.33333333 | G2: =IF(B2+C2=0,0,B2/(B2+C2)) -> 0 | H2: =IF(B2+E2=0,0,B2/(B2+E2)) -> 0 | I2: =IF(OR(G2=0,H2=0),0,2*G2*H2/(G2+H2)) -> 0
A3: K=2 | B3: =COUNTIFS(Sheet3!B2:B6,1,Sheet3!H2:H6,1) -> 0 | C3: =COUNTIFS(Sheet3!B2:B6,2,Sheet3!H2:H6,1) -> 1 | D3: =COUNTIFS(Sheet3!B2:B6,2,Sheet3!H2:H6,2) -> 1 | E3: =COUNTIFS(Sheet3!B2:B6,1,Sheet3!H2:H6,2) -> 3 | F3: =(B3+D3)/(B3+C3+D3+E3) -> 0.2 | G3: =IF(B3+C3=0,0,B3/(B3+C3)) -> 0 | H3: =IF(B3+E3=0,0,B3/(B3+E3)) -> 0 | I3: =IF(OR(G3=0,H3=0),0,2*G3*H3/(G3+H3)) -> 0
A4: K=3 | B4: =COUNTIFS(Sheet3!B2:B6,1,Sheet3!M2:M6,1) -> 1 | C4: =COUNTIFS(Sheet3!B2:B6,2,Sheet3!M2:M6,1) -> 0 | D4: =COUNTIFS(Sheet3!B2:B6,2,Sheet3!M2:M6,2) -> 2 | E4: =COUNTIFS(Sheet3!B2:B6,1,Sheet3!M2:M6,2) -> 2 | F4: =(B4+D4)/(B4+C4+D4+E4) -> 0.6 | G4: =IF(B4+C4=0,0,B4/(B4+C4)) -> 1 | H4: =IF(B4+E4=0,0,B4/(B4+E4)) -> 0.33333333 | I4: =IF(OR(G4=0,H4=0),0,2*G4*H4/(G4+H4)) -> 0.5
